<?xml version="1.0" encoding="UTF-8"?>
<robot name="MyArm300pi_EE_test_pt2">
  <joint name="gripper_base_to_gripper_left2" type="revolute">
    <origin xyz="-0.005 0.027 0. " rpy="0. -1.5707963 0. "/>
    <parent link="gripper_base"/>
    <child link="gripper_left2"/>
    <axis xyz="1. 0. 0."/>
    <limit lower="-0.7999999" upper="0.5" effort="0." velocity="5939047335254987724700441203225657344."/>
  </joint>
  <joint name="gripper_base_to_gripper_right2" type="revolute">
    <origin xyz="0.005 0.027 0. " rpy="0. -1.5707963 0. "/>
    <parent link="gripper_base"/>
    <child link="gripper_right2"/>
    <axis xyz="1. 0. 0."/>
    <limit lower="-0.5" upper="0.7999999" effort="0." velocity="5939047335254987724700441203225657344."/>
  </joint>
  <joint name="gripper_base_to_gripper_right3" type="revolute">
    <origin xyz="0.012 0.005 0. " rpy="0. -1.5707963 0. "/>
    <parent link="gripper_base"/>
    <child link="gripper_right3"/>
    <axis xyz="1. 0. 0."/>
    <limit lower="-0.15" upper="0.7" effort="0." velocity="5939047335254987724700441203225657344."/>
  </joint>
  <joint name="gripper_base_to_joint7" type="fixed">
    <origin xyz="0.0337681 0.0000224 0.0007262" rpy="3.1394386 0.0018566 1.5790223"/>
    <parent link="joint7"/>
    <child link="gripper_base"/>
  </joint>
  <joint name="gripper_controller" type="revolute">
    <origin xyz="-0.012 0.005 0. " rpy="0. -1.5707963 0. "/>
    <parent link="gripper_base"/>
    <child link="gripper_left3"/>
    <axis xyz="1. 0. 0."/>
    <limit lower="-0.7" upper="0.15" effort="1000." velocity="5939047335254987724700441203225657344."/>
  </joint>
  <joint name="gripper_left3_to_gripper_left1" type="revolute">
    <origin xyz="-0. 0.016 0.027" rpy="0.0000001 -0.0000005 -0.0000004"/>
    <parent link="gripper_left3"/>
    <child link="gripper_left1"/>
    <axis xyz="1. 0. 0."/>
    <limit lower="-0.5" upper="0.5" effort="0." velocity="5939047335254987724700441203225657344."/>
  </joint>
  <joint name="gripper_right3_to_gripper_right1" type="revolute">
    <origin xyz="0. 0.016 -0.027" rpy="0. 0. 0."/>
    <parent link="gripper_right3"/>
    <child link="gripper_right1"/>
    <axis xyz="1. 0. 0."/>
    <limit lower="-0.5" upper="0.5" effort="0." velocity="5939047335254987724700441203225657344."/>
  </joint>
  <joint name="joint1_to_base" type="revolute">
    <origin xyz="0. 0. 0.165" rpy="0. -1.5707963 0. "/>
    <parent link="base"/>
    <child link="joint1"/>
    <axis xyz="1. 0. 0."/>
    <limit lower="-2.7924999" upper="2.7924999" effort="1000." velocity="1."/>
  </joint>
  <joint name="joint2_to_joint1" type="revolute">
    <origin xyz="0. 0. 0." rpy="0. 0. 1.5708"/>
    <parent link="joint1"/>
    <child link="joint2"/>
    <axis xyz="1. 0. 0."/>
    <limit lower="-1.3961999" upper="1.3961999" effort="1000." velocity="1."/>
  </joint>
  <joint name="joint3_to_joint2" type="revolute">
    <origin xyz="0. -0.11 0. " rpy="0. 0. -1.5708"/>
    <parent link="joint2"/>
    <child link="joint3"/>
    <axis xyz="1. 0. 0."/>
    <limit lower="-2.8796998" upper="2.8796998" effort="1000." velocity="1."/>
  </joint>
  <joint name="joint4_to_joint3" type="revolute">
    <origin xyz="0. 0. 0." rpy="3.1415925 -0.0000026 -1.5708 "/>
    <parent link="joint3"/>
    <child link="joint4"/>
    <axis xyz="1. 0. 0."/>
    <limit lower="-1.7453" upper="1.3961999" effort="1000." velocity="1."/>
  </joint>
  <joint name="joint5_to_joint4" type="revolute">
    <origin xyz="0. -0.126 0. " rpy="0. 0. -1.5708"/>
    <parent link="joint4"/>
    <child link="joint5"/>
    <axis xyz="1. 0. 0."/>
    <limit lower="-2.8796998" upper="2.8796998" effort="1000." velocity="1."/>
  </joint>
  <joint name="joint6_to_joint5" type="revolute">
    <origin xyz="0. 0. 0." rpy="0. 0. 1.5708"/>
    <parent link="joint5"/>
    <child link="joint6"/>
    <axis xyz="1. 0. 0."/>
    <limit lower="-1.9198" upper="1.9198" effort="1000." velocity="1."/>
  </joint>
  <joint name="joint7_to_joint6" type="revolute">
    <origin xyz="0. -0.056 0. " rpy="0. 0. -1.5708"/>
    <parent link="joint6"/>
    <child link="joint7"/>
    <axis xyz="1. 0. 0."/>
    <limit lower="-2.8796998" upper="2.8796998" effort="1000." velocity="1."/>
  </joint>
  <joint name="root_joint" type="fixed">
    <origin xyz="0. 0. 0." rpy="0. 0. 0."/>
    <parent link="World"/>
    <child link="base"/>
  </joint>
  <link name="World">
    <visual>
      <origin xyz="0.0111862 0. 0. " rpy="0. 0. 0."/>
      <geometry>
        <mesh filename="meshes/CollisionMesh.obj" scale="1. 1. 1."/>
      </geometry>
    </visual>
    <visual>
      <origin xyz="-0.0250791 0.0603377 0.4543955" rpy="0. 0. 0."/>
      <geometry>
        <mesh filename="meshes/Cube.obj" scale="0.0325 0.0325 0.0325"/>
      </geometry>
    </visual>
    <visual>
      <origin xyz="-0.0023242 0.0021281 0.4935589" rpy="1.1243356 -1.5385494 -1.1245381"/>
      <geometry>
        <sphere radius="0.0150095"/>
      </geometry>
    </visual>
  </link>
  <link name="base">
    <inertial>
      <origin xyz="0. 0. 0." rpy="0. 0. 0."/>
      <mass value="0.000001"/>
      <inertia ixx="0." ixy="0." ixz="0." iyy="0." iyz="0." izz="0."/>
    </inertial>
    <visual>
      <origin xyz="0. 0. 0." rpy="0. 0. 0."/>
      <geometry>
        <mesh filename="meshes/base_visuals.obj" scale="1. 1. 1."/>
      </geometry>
    </visual>
    <visual>
      <origin xyz="0. 0. 0." rpy="0. 0. 0."/>
      <geometry>
        <mesh filename="meshes/base_collisions.obj" scale="1. 1. 1."/>
      </geometry>
    </visual>
    <visual>
      <origin xyz="0. 0. 0." rpy="0. 0. 0."/>
      <geometry>
        <sphere radius="0.0430467"/>
      </geometry>
    </visual>
    <collision>
      <origin xyz="0. 0. 0." rpy="0. 0. 0."/>
      <geometry>
        <mesh filename="meshes/base_collisions.obj" scale="1. 1. 1."/>
      </geometry>
    </collision>
  </link>
  <link name="gripper_base">
    <inertial>
      <origin xyz="0. 0. 0." rpy="0. 0. 0."/>
      <mass value="0.000001"/>
      <inertia ixx="0." ixy="0." ixz="0." iyy="0." iyz="0." izz="0."/>
    </inertial>
    <visual>
      <origin xyz="0. 0.0077 -0.012 " rpy="0. 0. 0."/>
      <geometry>
        <mesh filename="meshes/gripper_base_visuals.obj" scale="1. 1. 1."/>
      </geometry>
    </visual>
    <visual>
      <origin xyz="0. 0.0077 -0.012 " rpy="0. 0. 0."/>
      <geometry>
        <mesh filename="meshes/gripper_base_collisions.obj" scale="1. 1. 1."/>
      </geometry>
    </visual>
    <collision>
      <origin xyz="0. 0.0077 -0.012 " rpy="0. 0. 0."/>
      <geometry>
        <mesh filename="meshes/gripper_base_collisions.obj" scale="1. 1. 1."/>
      </geometry>
    </collision>
  </link>
  <link name="gripper_left1">
    <inertial>
      <origin xyz="0. 0. 0." rpy="0. 0. 0."/>
      <mass value="0.000001"/>
      <inertia ixx="0." ixy="0." ixz="0." iyy="0." iyz="0." izz="0."/>
    </inertial>
    <visual>
      <origin xyz="-0.012 -0.0133 -0.039 " rpy="-2.9133403 1.5707958 -2.91334 "/>
      <geometry>
        <mesh filename="meshes/gripper_left1_visuals.obj" scale="1. 1. 1."/>
      </geometry>
    </visual>
    <visual>
      <origin xyz="-0.012 -0.0133 0.039 " rpy="-2.9133403 1.5707958 -2.91334 "/>
      <geometry>
        <mesh filename="meshes/gripper_left1_collisions.obj" scale="1. 1. 1."/>
      </geometry>
    </visual>
    <collision>
      <origin xyz="-0.012 -0.0133 0.039 " rpy="-2.9133403 1.5707958 -2.91334 "/>
      <geometry>
        <mesh filename="meshes/gripper_left1_collisions.obj" scale="1. 1. 1."/>
      </geometry>
    </collision>
  </link>
  <link name="gripper_left2">
    <inertial>
      <origin xyz="0. 0. 0." rpy="0. 0. 0."/>
      <mass value="0.000001"/>
      <inertia ixx="0." ixy="0." ixz="0." iyy="0." iyz="0." izz="0."/>
    </inertial>
    <visual>
      <origin xyz="-0.012 -0.0195 -0.005 " rpy="0. 1.5707963 0. "/>
      <geometry>
        <mesh filename="meshes/gripper_left2_visuals.obj" scale="1. 1. 1."/>
      </geometry>
    </visual>
    <visual>
      <origin xyz="-0.012 -0.0195 0.005 " rpy="0. 1.5707963 0. "/>
      <geometry>
        <mesh filename="meshes/gripper_left2_collisions.obj" scale="1. 1. 1."/>
      </geometry>
    </visual>
    <collision>
      <origin xyz="-0.012 -0.0195 0.005 " rpy="0. 1.5707963 0. "/>
      <geometry>
        <mesh filename="meshes/gripper_left2_collisions.obj" scale="1. 1. 1."/>
      </geometry>
    </collision>
  </link>
  <link name="gripper_left3">
    <inertial>
      <origin xyz="0. 0. 0." rpy="0. 0. 0."/>
      <mass value="0.000001"/>
      <inertia ixx="0." ixy="0." ixz="0." iyy="0." iyz="0." izz="0."/>
    </inertial>
    <visual>
      <origin xyz="-0.012 0.0025 -0.012 " rpy="0. 1.5707963 0. "/>
      <geometry>
        <mesh filename="meshes/gripper_left3_visuals.obj" scale="1. 1. 1."/>
      </geometry>
    </visual>
    <visual>
      <origin xyz="-0.012 0.0025 -0.012 " rpy="0. 1.5707963 0. "/>
      <geometry>
        <mesh filename="meshes/gripper_left3_collisions.obj" scale="1. 1. 1."/>
      </geometry>
    </visual>
    <collision>
      <origin xyz="-0.012 0.0025 -0.012 " rpy="0. 1.5707963 0. "/>
      <geometry>
        <mesh filename="meshes/gripper_left3_collisions.obj" scale="1. 1. 1."/>
      </geometry>
    </collision>
  </link>
  <link name="gripper_right1">
    <inertial>
      <origin xyz="0. 0. 0." rpy="0. 0. 0."/>
      <mass value="0.000001"/>
      <inertia ixx="0." ixy="0." ixz="0." iyy="0." iyz="0." izz="0."/>
    </inertial>
    <visual>
      <origin xyz="-0.012 -0.0133 0.039 " rpy="0. 1.5707963 0. "/>
      <geometry>
        <mesh filename="meshes/gripper_right1_visuals.obj" scale="1. 1. 1."/>
      </geometry>
    </visual>
    <visual>
      <origin xyz="-0.012 -0.0133 0.039 " rpy="0. 1.5707963 0. "/>
      <geometry>
        <mesh filename="meshes/gripper_right1_collisions.obj" scale="1. 1. 1."/>
      </geometry>
    </visual>
    <collision>
      <origin xyz="-0.012 -0.0133 0.039 " rpy="0. 1.5707963 0. "/>
      <geometry>
        <mesh filename="meshes/gripper_right1_collisions.obj" scale="1. 1. 1."/>
      </geometry>
    </collision>
  </link>
  <link name="gripper_right2">
    <inertial>
      <origin xyz="0. 0. 0." rpy="0. 0. 0."/>
      <mass value="0.000001"/>
      <inertia ixx="0." ixy="0." ixz="0." iyy="0." iyz="0." izz="0."/>
    </inertial>
    <visual>
      <origin xyz="-0.012 -0.0195 0.005 " rpy="0.1549717 1.5707961 0.1549717"/>
      <geometry>
        <mesh filename="meshes/gripper_right2_visuals.obj" scale="1. 1. 1."/>
      </geometry>
    </visual>
    <visual>
      <origin xyz="-0.012 -0.0195 0.005 " rpy="0.1549717 1.5707961 0.1549717"/>
      <geometry>
        <mesh filename="meshes/gripper_right2_collisions.obj" scale="1. 1. 1."/>
      </geometry>
    </visual>
    <collision>
      <origin xyz="-0.012 -0.0195 0.005 " rpy="0.1549717 1.5707961 0.1549717"/>
      <geometry>
        <mesh filename="meshes/gripper_right2_collisions.obj" scale="1. 1. 1."/>
      </geometry>
    </collision>
  </link>
  <link name="gripper_right3">
    <inertial>
      <origin xyz="0. 0. 0." rpy="0. 0. 0."/>
      <mass value="0.000001"/>
      <inertia ixx="0." ixy="0." ixz="0." iyy="0." iyz="0." izz="0."/>
    </inertial>
    <visual>
      <origin xyz="-0.012 0.0025 0.012 " rpy="0. 1.5707963 0. "/>
      <geometry>
        <mesh filename="meshes/gripper_right3_visuals.obj" scale="1. 1. 1."/>
      </geometry>
    </visual>
    <visual>
      <origin xyz="-0.012 0.0025 0.012 " rpy="0. 1.5707963 0. "/>
      <geometry>
        <mesh filename="meshes/gripper_right3_collisions.obj" scale="1. 1. 1."/>
      </geometry>
    </visual>
    <collision>
      <origin xyz="-0.012 0.0025 0.012 " rpy="0. 1.5707963 0. "/>
      <geometry>
        <mesh filename="meshes/gripper_right3_collisions.obj" scale="1. 1. 1."/>
      </geometry>
    </collision>
  </link>
  <link name="joint1">
    <inertial>
      <origin xyz="0. 0. 0." rpy="0. 0. 0."/>
      <mass value="0.000001"/>
      <inertia ixx="0." ixy="0." ixz="0." iyy="0." iyz="0." izz="0."/>
    </inertial>
    <visual>
      <origin xyz="-0.085 0. 0. " rpy="0. 1.5707963 0. "/>
      <geometry>
        <mesh filename="meshes/joint1_visuals.obj" scale="1. 1. 1."/>
      </geometry>
    </visual>
    <visual>
      <origin xyz="-0.085 0. 0. " rpy="0. 1.5707963 0. "/>
      <geometry>
        <mesh filename="meshes/joint1_collisions.obj" scale="1. 1. 1."/>
      </geometry>
    </visual>
    <visual>
      <origin xyz="0. 0. 0." rpy="0. 1.5707963 0. "/>
      <geometry>
        <sphere radius="0.038742"/>
      </geometry>
    </visual>
    <collision>
      <origin xyz="-0.085 0. 0. " rpy="0. 1.5707963 0. "/>
      <geometry>
        <mesh filename="meshes/joint1_collisions.obj" scale="1. 1. 1."/>
      </geometry>
    </collision>
  </link>
  <link name="joint2">
    <inertial>
      <origin xyz="0. 0. 0." rpy="0. 0. 0."/>
      <mass value="0.000001"/>
      <inertia ixx="0." ixy="0." ixz="0." iyy="0." iyz="0." izz="0."/>
    </inertial>
    <visual>
      <origin xyz="0. 0. 0." rpy="1.5707937 -0.0000036 -1.5707964"/>
      <geometry>
        <mesh filename="meshes/joint2_visuals.obj" scale="1. 1. 1."/>
      </geometry>
    </visual>
    <visual>
      <origin xyz="0. 0. 0." rpy="1.5707937 -0.0000036 -1.5707964"/>
      <geometry>
        <mesh filename="meshes/joint2_collisions.obj" scale="1. 1. 1."/>
      </geometry>
    </visual>
    <visual>
      <origin xyz="0. 0. 0." rpy="0. 1.5707963 0. "/>
      <geometry>
        <sphere radius="0.0383546"/>
      </geometry>
    </visual>
    <collision>
      <origin xyz="0. 0. 0." rpy="1.5707937 -0.0000036 -1.5707964"/>
      <geometry>
        <mesh filename="meshes/joint2_collisions.obj" scale="1. 1. 1."/>
      </geometry>
    </collision>
  </link>
  <link name="joint3">
    <inertial>
      <origin xyz="0. 0. 0." rpy="0. 0. 0."/>
      <mass value="0.000001"/>
      <inertia ixx="0." ixy="0." ixz="0." iyy="0." iyz="0." izz="0."/>
    </inertial>
    <visual>
      <origin xyz="-0.054 0. 0. " rpy="0. 1.5707963 0. "/>
      <geometry>
        <mesh filename="meshes/joint3_visuals.obj" scale="1. 1. 1."/>
      </geometry>
    </visual>
    <visual>
      <origin xyz="-0.054 0. 0. " rpy="0. 1.5707963 0. "/>
      <geometry>
        <mesh filename="meshes/joint3_collisions.obj" scale="1. 1. 1."/>
      </geometry>
    </visual>
    <visual>
      <origin xyz="0. 0. 0." rpy="0. 1.5707963 0. "/>
      <geometry>
        <sphere radius="0.028243"/>
      </geometry>
    </visual>
    <collision>
      <origin xyz="-0.054 0. 0. " rpy="0. 1.5707963 0. "/>
      <geometry>
        <mesh filename="meshes/joint3_collisions.obj" scale="1. 1. 1."/>
      </geometry>
    </collision>
  </link>
  <link name="joint4">
    <inertial>
      <origin xyz="0. 0. 0." rpy="0. 0. 0."/>
      <mass value="0.000001"/>
      <inertia ixx="0." ixy="0." ixz="0." iyy="0." iyz="0." izz="0."/>
    </inertial>
    <visual>
      <origin xyz="0. 0. 0." rpy="-1.5707964 -0.0000036 -1.5707964"/>
      <geometry>
        <mesh filename="meshes/joint4_visuals.obj" scale="1. 1. 1."/>
      </geometry>
    </visual>
    <visual>
      <origin xyz="0. 0. 0." rpy="-1.5707964 -0.0000036 -1.5707964"/>
      <geometry>
        <mesh filename="meshes/joint4_collisions.obj" scale="1. 1. 1."/>
      </geometry>
    </visual>
    <visual>
      <origin xyz="0. 0. 0." rpy="0. 1.5707963 0. "/>
      <geometry>
        <sphere radius="0.0313811"/>
      </geometry>
    </visual>
    <collision>
      <origin xyz="0. 0. 0." rpy="-1.5707964 -0.0000036 -1.5707964"/>
      <geometry>
        <mesh filename="meshes/joint4_collisions.obj" scale="1. 1. 1."/>
      </geometry>
    </collision>
  </link>
  <link name="joint5">
    <inertial>
      <origin xyz="0. 0. 0." rpy="0. 0. 0."/>
      <mass value="0.000001"/>
      <inertia ixx="0." ixy="0." ixz="0." iyy="0." iyz="0." izz="0."/>
    </inertial>
    <visual>
      <origin xyz="-0.051 0. 0. " rpy="1.5707964 -1.5707937 1.5707964"/>
      <geometry>
        <mesh filename="meshes/joint5_visuals.obj" scale="1. 1. 1."/>
      </geometry>
    </visual>
    <visual>
      <origin xyz="-0.051 0. 0. " rpy="1.5707964 -1.5707937 1.5707964"/>
      <geometry>
        <mesh filename="meshes/joint5_collisions.obj" scale="1. 1. 1."/>
      </geometry>
    </visual>
    <visual>
      <origin xyz="0. 0. 0." rpy="0. 1.5707963 0. "/>
      <geometry>
        <sphere radius="0.0228768"/>
      </geometry>
    </visual>
    <collision>
      <origin xyz="-0.051 0. 0. " rpy="1.5707964 -1.5707937 1.5707964"/>
      <geometry>
        <mesh filename="meshes/joint5_collisions.obj" scale="1. 1. 1."/>
      </geometry>
    </collision>
  </link>
  <link name="joint6">
    <inertial>
      <origin xyz="0. 0. 0." rpy="0. 0. 0."/>
      <mass value="0.000001"/>
      <inertia ixx="0." ixy="0." ixz="0." iyy="0." iyz="0." izz="0."/>
    </inertial>
    <visual>
      <origin xyz="0. 0. 0." rpy="-1.5707964 -0.0000036 -1.5707964"/>
      <geometry>
        <mesh filename="meshes/joint6_visuals.obj" scale="1. 1. 1."/>
      </geometry>
    </visual>
    <visual>
      <origin xyz="0. 0. 0." rpy="-1.5707964 -0.0000036 -1.5707964"/>
      <geometry>
        <mesh filename="meshes/joint6_collisions.obj" scale="1. 1. 1."/>
      </geometry>
    </visual>
    <visual>
      <origin xyz="0. 0. 0." rpy="0. 1.5707963 0. "/>
      <geometry>
        <sphere radius="0.0228768"/>
      </geometry>
    </visual>
    <collision>
      <origin xyz="0. 0. 0." rpy="-1.5707964 -0.0000036 -1.5707964"/>
      <geometry>
        <mesh filename="meshes/joint6_collisions.obj" scale="1. 1. 1."/>
      </geometry>
    </collision>
  </link>
  <link name="joint7">
    <inertial>
      <origin xyz="0. 0. 0." rpy="0. 0. 0."/>
      <mass value="0.000001"/>
      <inertia ixx="0." ixy="0." ixz="0." iyy="0." iyz="0." izz="0."/>
    </inertial>
    <visual>
      <origin xyz="-0.009 0. 0. " rpy="-1.5707964 -0.0000036 -1.5707964"/>
      <geometry>
        <mesh filename="meshes/joint7_visuals.obj" scale="1. 1. 1."/>
      </geometry>
    </visual>
    <visual>
      <origin xyz="-0.009 0. 0. " rpy="-1.5707964 -0.0000036 -1.5707964"/>
      <geometry>
        <mesh filename="meshes/joint7_collisions.obj" scale="1. 1. 1."/>
      </geometry>
    </visual>
    <visual>
      <origin xyz="0. 0. 0." rpy="0. 1.5707963 0. "/>
      <geometry>
        <sphere radius="0.0185302"/>
      </geometry>
    </visual>
    <collision>
      <origin xyz="-0.009 0. 0. " rpy="-1.5707964 -0.0000036 -1.5707964"/>
      <geometry>
        <mesh filename="meshes/joint7_collisions.obj" scale="1. 1. 1."/>
      </geometry>
    </collision>
  </link>
</robot>
